<?xml version="1.0" encoding="utf-8"?>
<!-- This URDF was automatically created by SolidWorks to URDF Exporter! Originally created by Stephen Brawner (brawner@gmail.com) 
     Commit Version: 1.5.1-0-g916b5db  Build Version: 1.5.7152.31018
     For more information, please see http://wiki.ros.org/sw_urdf_exporter -->
<robot
  name="dummy2-SLDASM">
  <link
    name="base_link">
    <inertial>
      <origin
        xyz="0.0414130360937032 0.0406718044276676 0.0386845489683347"
        rpy="0 0 0" />
      <mass
        value="0.387673822333728" />
      <inertia
        ixx="0.000777649014838783"
        ixy="-2.70111444450116E-07"
        ixz="-7.00973333936696E-06"
        iyy="0.000718387993685806"
        iyz="-8.02049294338553E-07"
        izz="0.000791143378494355" />
    </inertial>
    <visual>
      <origin
        xyz="0 0 0"
        rpy="0 0 0" />
      <geometry>
        <mesh
          filename="package://dummy2-gripperv3_description/meshes/base_link.STL" />
      </geometry>
      <material
        name="">
        <color
          rgba="1 1 1 1" />
      </material>
    </visual>
    <collision>
      <origin
        xyz="0 0 0"
        rpy="0 0 0" />
      <geometry>
        <mesh
          filename="package://dummy2-gripperv3_description/meshes/base_link.STL" />
      </geometry>
    </collision>
  </link>
  <link
    name="l1">
    <inertial>
      <origin
        xyz="0.0269163124747258 -0.0056237301524306 0.0344105082650809"
        rpy="0 0 0" />
      <mass
        value="0.192001303218632" />
      <inertia
        ixx="0.000147334590447093"
        ixy="1.12051433464132E-05"
        ixz="-4.26888163188289E-05"
        iyy="0.000157405351191848"
        iyz="7.79877632367723E-06"
        izz="0.000177766468080378" />
    </inertial>
    <visual>
      <origin
        xyz="0 0 0"
        rpy="0 0 0" />
      <geometry>
        <mesh
          filename="package://dummy2-gripperv3_description/meshes/l1.STL" />
      </geometry>
      <material
        name="">
        <color
          rgba="1 1 1 1" />
      </material>
    </visual>
    <collision>
      <origin
        xyz="0 0 0"
        rpy="0 0 0" />
      <geometry>
        <mesh
          filename="package://dummy2-gripperv3_description/meshes/l1.STL" />
      </geometry>
    </collision>
  </link>
  <joint
    name="j1"
    type="revolute">
    <origin
      xyz="0.0392540163906673 0.0407323237392788 0.0820000000000018"
      rpy="0 0 0" />
    <parent
      link="base_link" />
    <child
      link="l1" />
    <axis
      xyz="0 0 1" />
    <limit
      lower="-3.14"
      upper="3.14"
      effort="0"
      velocity="0" />
  </joint>
  <link
    name="l2">
    <inertial>
      <origin
        xyz="-0.0024744 0.10233 -0.022453"
        rpy="0 0 0" />
      <mass
        value="0.31882" />
      <inertia
        ixx="0.0010182"
        ixy="5.4742E-05"
        ixz="-6.4406E-06"
        iyy="0.00020838"
        iyz="0.00010214"
        izz="0.0009056" />
    </inertial>
    <visual>
      <origin
        xyz="0 0 0"
        rpy="0 0 0" />
      <geometry>
        <mesh
          filename="package://dummy2-gripperv3_description/meshes/l2.STL" />
      </geometry>
      <material
        name="">
        <color
          rgba="1 1 1 1" />
      </material>
    </visual>
    <collision>
      <origin
        xyz="0 0 0"
        rpy="0 0 0" />
      <geometry>
        <mesh
          filename="package://dummy2-gripperv3_description/meshes/l2.STL" />
      </geometry>
    </collision>
  </link>
  <joint
    name="j2"
    type="revolute">
    <origin
      xyz="0.0391139899839922 -0.0475202565028203 0.0424031868280582"
      rpy="1.57079632679491 0 0.0217856610140804" />
    <parent
      link="l1" />
    <child
      link="l2" />
    <axis
      xyz="0 0 -1" />
    <limit
      lower="-3.14"
      upper="3.14"
      effort="0"
      velocity="0" />
  </joint>
  <link
    name="l3">
    <inertial>
      <origin
        xyz="0.00982202582825078 -0.065705588173923 -0.0227777009132376"
        rpy="0 0 0" />
      <mass
        value="0.177031969385558" />
      <inertia
        ixx="0.000196740625169965"
        ixy="6.39357247299932E-06"
        ixz="-1.2869164739589E-06"
        iyy="0.000100666168469324"
        iyz="-2.26749158246386E-05"
        izz="0.000243511147945243" />
    </inertial>
    <visual>
      <origin
        xyz="0 0 0"
        rpy="0 0 0" />
      <geometry>
        <mesh
          filename="package://dummy2-gripperv3_description/meshes/l3.STL" />
      </geometry>
      <material
        name="">
        <color
          rgba="1 1 1 1" />
      </material>
    </visual>
    <collision>
      <origin
        xyz="0 0 0"
        rpy="0 0 0" />
      <geometry>
        <mesh
          filename="package://dummy2-gripperv3_description/meshes/l3.STL" />
      </geometry>
    </collision>
  </link>
  <joint
    name="j3"
    type="revolute">
    <origin
      xyz="-0.00647360594018897 0.168725443290264 0.0191499999999696"
      rpy="0 0 -3.14159265358979" />
    <parent
      link="l2" />
    <child
      link="l3" />
    <axis
      xyz="0 0 -1" />
    <limit
      lower="-3.14"
      upper="3.14"
      effort="0"
      velocity="0" />
  </joint>
  <link
    name="l4">
    <inertial>
      <origin
        xyz="0.00875633257448984 -0.00120706473295173 0.0721271140835659"
        rpy="0 0 0" />
      <mass
        value="0.169343235311395" />
      <inertia
        ixx="0.000272837799469975"
        ixy="-1.37510341482809E-06"
        ixz="-4.44369379231373E-05"
        iyy="0.000325021018054113"
        iyz="-5.85486926747817E-06"
        izz="8.92852063803601E-05" />
    </inertial>
    <visual>
      <origin
        xyz="0 0 0"
        rpy="0 0 0" />
      <geometry>
        <mesh
          filename="package://dummy2-gripperv3_description/meshes/l4.STL" />
      </geometry>
      <material
        name="">
        <color
          rgba="1 1 1 1" />
      </material>
    </visual>
    <collision>
      <origin
        xyz="0 0 0"
        rpy="0 0 0" />
      <geometry>
        <mesh
          filename="package://dummy2-gripperv3_description/meshes/l4.STL" />
      </geometry>
    </collision>
  </link>
  <joint
    name="j4"
    type="revolute">
    <origin
      xyz="-0.037831 -0.056583 -0.02515"
      rpy="3.101 1.5708 0" />
    <parent
      link="l3" />
    <child
      link="l4" />
    <axis
      xyz="0 0 1" />
    <limit
      lower="-3.14"
      upper="3.14"
      effort="0"
      velocity="0" />
  </joint>
  <link
    name="l5">
    <inertial>
      <origin
        xyz="0.0503111008189627 -0.000539752076599731 -0.0586137579632375"
        rpy="0 0 0" />
      <mass
        value="0.0670202076275983" />
      <inertia
        ixx="1.65218379011082E-05"
        ixy="3.15300079319617E-07"
        ixz="-9.04914206209732E-06"
        iyy="4.584421849236E-05"
        iyz="6.5228627023569E-08"
        izz="4.0972293581658E-05" />
    </inertial>
    <visual>
      <origin
        xyz="0 0 0"
        rpy="0 0 0" />
      <geometry>
        <mesh
          filename="package://dummy2-gripperv3_description/meshes/l5.STL" />
      </geometry>
      <material
        name="">
        <color
          rgba="1 1 1 1" />
      </material>
    </visual>
    <collision>
      <origin
        xyz="0 0 0"
        rpy="0 0 0" />
      <geometry>
        <mesh
          filename="package://dummy2-gripperv3_description/meshes/l5.STL" />
      </geometry>
    </collision>
  </link>
  <joint
    name="j5"
    type="revolute">
    <origin
      xyz="-0.014464 -4.7163E-05 0.11"
      rpy="1.5708 -1.5302 -1.5675" />
    <parent
      link="l4" />
    <child
      link="l5" />
    <axis
      xyz="0 0 1" />
    <limit
      lower="-3.14"
      upper="3.14"
      effort="0"
      velocity="0" />
  </joint>
  <link
    name="l6">
    <inertial>
      <origin
        xyz="1.14605602785645E-10 4.2896131091652E-11 -0.0028358915417413"
        rpy="0 0 0" />
      <mass
        value="0.00415080295459014" />
      <inertia
        ixx="4.39181646124603E-07"
        ixy="-4.17234486196236E-11"
        ixz="5.18167500674017E-15"
        iyy="4.38951442749453E-07"
        iyz="1.79463377636992E-15"
        izz="3.0018416400469E-07" />
    </inertial>
    <visual>
      <origin
        xyz="0 0 0"
        rpy="0 0 0" />
      <geometry>
        <mesh
          filename="package://dummy2-gripperv3_description/meshes/l6.STL" />
      </geometry>
      <material
        name="">
        <color
          rgba="1 1 1 1" />
      </material>
    </visual>
    <collision>
      <origin
        xyz="0 0 0"
        rpy="0 0 0" />
      <geometry>
        <mesh
          filename="package://dummy2-gripperv3_description/meshes/l6.STL" />
      </geometry>
    </collision>
  </link>
  <joint
    name="j6"
    type="revolute">
    <origin
      xyz="0.106996171166484 -0.000960101234833921 -0.0526108232633675"
      rpy="-1.57079632679544 1.56753815017486 -1.58276052327955" />
    <parent
      link="l5" />
    <child
      link="l6" />
    <axis
      xyz="0 0 -1" />
    <limit
      lower="-3.14"
      upper="3.14"
      effort="0"
      velocity="0" />
  </joint>
</robot>